<?xml version="1.0" ?>
<robot name="cube_petit" xmlns:xacro="http://ros.org/wiki/xacro">
  <material name="gray">
    <color rgba="0.5 0.5 0.5 2.5"/>
  </material>
  <material name="red">
    <color rgba="1.0 0.0 0.0 2.5"/>
  </material>


  <link name="base_link"/>


  <joint name="body_joint" type="fixed">
    <parent link="base_link"/>
    <child link="body_link"/>
    <origin rpy="0 0 0" xyz="0.0 0 0.125"/>
  </joint>
  <link name="body_link">
    <inertial>
      <origin rpy="0 0 0" xyz="0 0 0"/>
      <mass value="31.20594944"/>
      <inertia ixx="1.79583172" ixy="0.03278618" ixz="0.02535482" iyy="1.55345103" iyz="0.01272625" izz="1.22908514"/>
    </inertial>
    <visual>
      <origin rpy="0 0 0" xyz="0 0 0"/>
      <geometry>
        <box size="0.22 0.22 0.145"/>
      </geometry>
      <material name="gray"/>
    </visual>
    <collision>
      <origin rpy="0 0 0" xyz="0 0 0"/>
      <geometry>
        <box size="0.22 0.22 0.145"/>
      </geometry>
    </collision>
  </link>
  <gazebo reference="body_link">
    <material>Gazebo/Gray</material>
    <mu1 value="0.5"/>
    <kp value="500000"/>
    <kd value="100"/>
  </gazebo>


  <joint name="laser_joint" type="fixed">
    <parent link="body_link"/>
    <child link="pacecat_link"/>
    <origin rpy="0 0 0" xyz="0.0 0 0.1175"/>
  </joint>
  <link name="pacecat_link">
    <inertial>
      <origin rpy="0 0 0" xyz="0 0 0"/>
      <mass value="5.20594944"/>
      <inertia ixx="1.79583172" ixy="0.03278618" ixz="0.02535482" iyy="1.55345103" iyz="0.01272625" izz="1.22908514"/>
    </inertial>
    <visual>
      <origin rpy="0 0 0" xyz="0 0 0"/>
      <geometry>
        <cylinder length="0.03" radius="0.02"/>
      </geometry>
      <material name="red"/>
    </visual>
    <collision>
      <origin rpy="0 0 0" xyz="0 0 0"/>
      <geometry>
        <cylinder length="0.03" radius="0.02"/>
      </geometry>
    </collision>
  </link>
  <gazebo reference="pacecat_link">
    <material>Gazebo/Red</material>
    <mu1 value="0.5"/>
    <kp value="500000"/>
    <kd value="100"/>
  </gazebo>

  <joint name="left_wheel_joint" type="continuous">
    <origin rpy="0 0 0" xyz="0.0 0.12 -0.09"/>
    <parent link="body_link"/>
    <child link="left_wheel_link"/>
    <axis xyz="0 1 0"/>
  </joint>
  <transmission name="left_wheel_trans" type="SimpleTransmission">
    <type>transmission_interface/SimpleTransmission</type>
    <actuator name="left_wheel_motor">
      <mechanicalReduction>1</mechanicalReduction>
    </actuator>
    <joint name="left_wheel_joint">
      <hardwareInterface>hardware_interface/VelocityJointInterface</hardwareInterface>
    </joint>
  </transmission>
  <link name="left_wheel_link">
    <inertial>
      <origin rpy="0 0 0" xyz="0 0 0"/>
      <mass value="3.16354494"/>
      <inertia ixx="0.02296002" ixy="0.00000000" ixz="0.00000000" iyy="0.04452360" iyz="-0.00000001" izz="0.02296002"/>
    </inertial>
    <visual>
      <origin rpy="1.57079632679 0 0" xyz="0 0 0"/>
      <geometry>
        <cylinder length="0.02" radius="0.0325"/>
      </geometry>
      <material name="red"/>
    </visual>
    <collision>
      <origin rpy="1.57079632679 0 0" xyz="0 0 0"/>
      <geometry>
        <cylinder length="0.02" radius="0325"/>
      </geometry>
    </collision>
  </link>
  <gazebo reference="left_wheel_link">
    <material>Gazebo/Red</material>
    <mu1 value="2.5"/>
    <!-- <mu2 value="2.5" /> -->
    <kp value="500000"/>
    <kd value="100"/>
  </gazebo>


  <joint name="right_wheel_joint" type="continuous">
    <origin rpy="0 0 0" xyz="0.0 -0.12 -0.09"/>
    <parent link="body_link"/>
    <child link="right_wheel_link"/>
    <axis xyz="0 1 0"/>
  </joint>
  <transmission name="right_wheel_trans" type="SimpleTransmission">
    <type>transmission_interface/SimpleTransmission</type>
    <actuator name="right_wheel_motor">
      <mechanicalReduction>1</mechanicalReduction>
    </actuator>
    <joint name="right_wheel_joint">
      <hardwareInterface>hardware_interface/VelocityJointInterface</hardwareInterface>
    </joint>
  </transmission>
  <link name="right_wheel_link">
    <inertial>
      <origin rpy="0 0 0" xyz="0 0 0"/>
      <mass value="3.16354494"/>
      <inertia ixx="0.02296002" ixy="0.00000000" ixz="0.00000000" iyy="0.04452360" iyz="-0.00000001" izz="0.02296002"/>
    </inertial>
    <visual>
      <origin rpy="1.57079632679 0 0" xyz="0 0 0"/>
      <geometry>
        <cylinder length="0.02" radius="0.0325"/>
      </geometry>
      <material name="red"/>
    </visual>
    <collision>
      <origin rpy="1.57079632679 0 0" xyz="0 0 0"/>
      <geometry>
        <cylinder length="0.02" radius="0.0325"/>
      </geometry>
    </collision>
  </link>
  <gazebo reference="right_wheel_link">
    <material>Gazebo/Red</material>
    <mu1 value="2.5"/>
    <!-- <mu2 value="2.5" /> -->
    <kp value="500000"/>
    <kd value="100"/>
  </gazebo>


  <joint name="ball_joint4" type="fixed">
    <parent link="base_link"/>
    <child link="ball_link4"/>
    <origin rpy="0 0 0" xyz="-0.063 0.073 0.04"/>
  </joint>
  <link name="ball_link4">
    <inertial>
      <origin rpy="0 0 0" xyz="0 0 0"/>
      <mass value="1.0"/>
      <inertia ixx="0.001" ixy="0.0" ixz="0.0" iyy="0.001" iyz="0.0" izz="0.001"/>
    </inertial>
    <visual>
      <origin rpy="0 0 0" xyz="0 0 0"/>
      <geometry>
        <sphere radius="0.04"/>
      </geometry>
      <material name="gray"/>
    </visual>
    <collision>
      <origin rpy="0 0 0" xyz="0 0 0"/>
      <geometry>
        <sphere radius="0.04"/>
      </geometry>
      <material name="gray"/>
    </collision>
  </link>
  <gazebo reference="ball_link4">
    <material>Gazebo/Gray</material>
    <mu1 value="0.01"/>
    <kp value="2000000"/>
    <kd value="100"/>
    <!-- <mu2 value="0.5" /> -->
  </gazebo>

  <joint name="ball_joint1" type="fixed">
    <parent link="base_link"/>
    <child link="ball_link1"/>
    <origin rpy="0 0 0" xyz="0.063 0.073 0.04"/>
  </joint>
  <link name="ball_link1">
    <inertial>
      <origin rpy="0 0 0" xyz="0 0 0"/>
      <mass value="1.0"/>
      <inertia ixx="0.001" ixy="0.0" ixz="0.0" iyy="0.001" iyz="0.0" izz="0.001"/>
    </inertial>
    <visual>
      <origin rpy="0 0 0" xyz="0 0 0"/>
      <geometry>
        <sphere radius="0.04"/>
      </geometry>
      <material name="gray"/>
    </visual>
    <collision>
      <origin rpy="0 0 0" xyz="0 0 0"/>
      <geometry>
        <sphere radius="0.04"/>
      </geometry>
      <material name="gray"/>
    </collision>
  </link>
  <gazebo reference="ball_link1">
    <material>Gazebo/Gray</material>
    <mu1 value="0.01"/>
    <kp value="2000000"/>
    <kd value="100"/>
    <!-- <mu2 value="0.5" /> -->
  </gazebo>

    <joint name="ball_joint2" type="fixed">
    <parent link="base_link"/>
    <child link="ball_link2"/>
    <origin rpy="0 0 0" xyz="0.063 -0.073 0.04"/>
  </joint>
  <link name="ball_link2">
    <inertial>
      <origin rpy="0 0 0" xyz="0 0 0"/>
      <mass value="1.0"/>
      <inertia ixx="0.001" ixy="0.0" ixz="0.0" iyy="0.001" iyz="0.0" izz="0.001"/>
    </inertial>
    <visual>
      <origin rpy="0 0 0" xyz="0 0 0"/>
      <geometry>
        <sphere radius="0.04"/>
      </geometry>
      <material name="gray"/>
    </visual>
    <collision>
      <origin rpy="0 0 0" xyz="0 0 0"/>
      <geometry>
        <sphere radius="0.04"/>
      </geometry>
      <material name="gray"/>
    </collision>
  </link>
  <gazebo reference="ball_link2">
    <material>Gazebo/Gray</material>
    <mu1 value="0.01"/>
    <kp value="2000000"/>
    <kd value="100"/>
    <!-- <mu2 value="0.5" /> -->
  </gazebo>

    <joint name="ball_joint3" type="fixed">
    <parent link="base_link"/>
    <child link="ball_link3"/>
    <origin rpy="0 0 0" xyz="-0.063 -0.073 0.04"/>
  </joint>
  <link name="ball_link3">
    <inertial>
      <origin rpy="0 0 0" xyz="0 0 0"/>
      <mass value="1.0"/>
      <inertia ixx="0.001" ixy="0.0" ixz="0.0" iyy="0.001" iyz="0.0" izz="0.001"/>
    </inertial>
    <visual>
      <origin rpy="0 0 0" xyz="0 0 0"/>
      <geometry>
        <sphere radius="0.04"/>
      </geometry>
      <material name="gray"/>
    </visual>
    <collision>
      <origin rpy="0 0 0" xyz="0 0 0"/>
      <geometry>
        <sphere radius="0.04"/>
      </geometry>
      <material name="gray"/>
    </collision>
  </link>
  <gazebo reference="ball_link3">
    <material>Gazebo/Gray</material>
    <mu1 value="0.01"/>
    <kp value="2000000"/>
    <kd value="100"/>
    <!-- <mu2 value="0.5" /> -->
  </gazebo>


  <gazebo>
    <plugin filename="libgazebo_ros_control.so" name="gazebo_ros_control">
      <robotNamespace>/cube_petit</robotNamespace>
      <legacyModeNS>true</legacyModeNS>
    </plugin>
  </gazebo>
</robot>

